Workbook
Name ACTION: #REF!
Name ACTION: #REF!
Name ACTION: #REF!

Sheet Cover
C2: TEST PLAN
B4: Project Name | C4: Fshop | F4: Reviewer
B5: Project Code | C5: Fshop | F5: Review date
B6: Creator | C6: Lê Chí Trường | F6: Approver
B7: Version | C7: v1.0 | F7: Approval Date
B9: Record of change
B10: Effective Date | C10: Version | D10: Change Item | E10: A, D, M | F10: Change description
B11: 45595 | C11: v1.0 | D11: Initial
B14: Index
B15: Sheet Name | C15: Description | G15: Note
B16: Cover | C16: Title page
B17: Test Policy | C17: - General policy for Test process, Test case design, Test Data - List of requirements to Test/not Test - Exit criteria for testing - Suspension criteria and Resumption requirements
B18: Test Management | C18: - Test scope - Deliverable - Management method - Risk - Assumption - Training plan
B19: Test Strategy | C19: Identification of Test level, Test types, Test environments, Test data and Enviroment for test
B20: Master Schedule | C20: Introduction and Define team, master schedule for testing
B21: Appendix | C21: - Description and detailed definition of Test level, types and techniques - List of Terminologies and definition/explanation | G21: For Reference only
B23: Reference Document
B24: Name | F24: Version | G24: Note
B25: Fshop_ScreenDesign_v0.5 | F25: 0.5

Sheet Test Policy
A2: Test Policy
B4: Test process policy
B5: Description of policies of testing process.
B6: # | C6: Description | D6: Responsibility | E6: Note
B7: 1
B8: 2
B11: Test case design policy
B12: Description of policies of test case design.
B13: # | C13: Items | D13: Note
B14: 1
B15: 2
B17: Quality metric
B18: Description of target
B19: # | C19: Items | D19: Target | E19: Note
B23: Pass/Fail Criteria
B24: The conditions that the testing must satisfy to end test.
B25: # | C25: Criteria | D25: Priority | E25: Note
B26: 1 | C26: 80% of completed test cases / total test cases (test coverage > 80%) | E26: Carry out test cases with highest priority first, then increase gradually.
B27: 2 | C27: Test successful coverage >= 80%
B28: 3 | C28: Software is correct with SRS
B30: Suspension Criteria and Resumption Requirements
B31: Specify when to pause in a series of tests and requirements for resumption of test activities.
B32: # | C32: Suspension Criteria | D32: Note
B33: 1 | C33: When a defect is introduced that cannot allow any further testing
B34: 2 | C34: A specific holiday shuts down both development and testing (Tet Holiday)
B35: 3 | C35: If there is any network, hardware problem in the organisation, we can suspend testing
B36: 4 | C36: If we got more pending requests with the development team
B37: # | C37: Resumption Requirements | D37: Note
B38: 1 | C38: When the particular issue has been addressed and solved

Sheet Test Management
E2: Test Management
A4: Test Scope
A5: Listing of test items in test process.
A6: # | B6: Items | D6: Description | F6: Responsibility | G6: Note
A7: 1 | B7: Create test plan | D7: Make a test plan | F7: Leader / Testers
A8: 2 | B8: Create test design | D8: Design test cases | F8: Tester
A9: 3 | B9: Create test cases | D9: Create test cases based on requirements | F9: Tester
A10: 4 | B10: Create test data | D10: Prepare test data | F10: Teseter
A11: 5 | B11: Execute system test | D11: Execute test cases | F11: Teseter
A12: 6 | B12: Defects list | D12: Report any errors that arise | F12: Teseter
A13: 7 | B13: Create test report | D13: Synthesize and prepare test reports | F13: Leader / Testers
A15: Deliverables
A16: Listing of documents will be delivered of test process.
A17: # | B17: Deliverables | D17: Delivered date | E17: Delivered by | F17: Delivered to | G17: Note
A18: 1 | B18: Test plan | D18: 45595 | E18: Test leader | F18: Test manager, Team | G18: This document itself
A19: 2 | B19: Test cases | D19: 45595 | E19: Test leader | F19: Test manager, Team
A20: 3 | B20: Defect logs | D20: 45595 | E20: Test leader | F20: Test manager, Team
A21: 4 | B21: Test report | D21: 45595 | E21: Test leader | F21: Test manager, Team
A23: Management method
A24: Describe the management method of test process.
A25: # | B25: Object | D25: Method | G25: Note
A26: 1 | B26: Test Execution | D26: Manage progress and daily reports | G26: Use project management tools (ex: Trello,..)
A27: 2 | B27: Defect Management | D27: Monitor and analyze arising errors
A28: 3 | B28: Test Case Review | D28: Đánh giá và phê duyệt test case | G28: Weekly meetings with the team
A30: Risks
A31: Listing of all risks of test process and action to mitigate the risk and do if risk become reality.
A32: # | B32: Condition | E32: Mitigation | G32: Contingency
A33: 1 | B33: Team members lack experience in software testing domain | E33: Plan training course to skill up your members | G33: 1. Connect with a training organization 2. Attend mandatory training 3. Quality test
A34: 2 | B34: The development team improved the code which led to the testing process being paused | E34: Accept this risk | G34: Contact the development team
A35: 3 | B35: The project schedule is too tight; it's hard to complete this project on time | E35: Set test priority for each test case and execute the test case with the highest priority | G35: 1. Determine the priority for each test case 2. Set priority for each test case 3. Follow the priority level
A36: 4 | B36: Members misunderstood the request | E36: Organize to review and analyze requirements to member before starting the testing process | G36: 1. Hold a meeting 2. Review required 3. Inspections
A37: 5 | B37: Employees reduce working performance after Tet holiday | E37: Accept this risk | G37: OT to keep up with the schedule
A39: Assumption
A40: Listing of all assumption of test process.
A41: # | B41: Type | D41: Description
A42: 1 | B42: Environmental assumptions | D42: The testing environment will be fully prepared before testing begins.
A43: 2 | B43: Assume requirements | D43: All requirements will be finalized before test case design begins.
A45: Training Plan
A46: Plan training for test team.
A47: # | B47: Training Topic | D47: Description | F47: Responsibility | G47: Start Date | H47: End Date
...

Sheet Test Strategy
D2: Test Strategy
B4: Test Objective:
B5: To ensure doesn’t contain serious bugs before release to customer, to confirm that the system has met the requirements
B8: Test stages & techniques
B9: Listing of all test stages of project, and test techniques must be done of every test stages.
B10: Test stage | C10: Unit testing | D10: Integration Testing | E10: System Testing | F10: User acceptance testing
B11: Test techniques
B12: White box testing | C12: x | E12: x
B13: Black box testing | D13: x | E13: x | F13: x
B14: Responsibility | C14: Developer | D14: Tester | E14: Tester | F14: Tester
B17: Requirements to be tested
B18: Listing of what is to be tested from the USERS viewpoint of what the system does.
B19: Feature/Function | D19: Document which is testing base on | G19: Note
B20: All Functions of the Fshop system described in screen design document, the functions are tested in order of priority from high to low (highest priority tested first) | D20: Fshop_ScreenDesign_v0.5
B23: Test environment
B24: Listing of environments use in test process.
B25: Type | C25: Environment | G25: Note
B26: Hardware | C26: Laptop, Tablet, Smartphone | G26: Standard Fsoft
B27: OS | C27: Window 10 64bit Mac10.14.5 Android 6.0 or higher
B28: Software | C28: Chrome version 78.0.3904.97 Firefox 70.0 Edge 44.18362.329.0
B29: Database | C29: MS SQL
B30: Browser | C30: IE/FireFox, Chrome
B31: Network configured | C31: LAN Wifi

Sheet Master Schedule
C2: Master Schedule
A4: Project Team
A5: Listing of all workers join the testing process
A6: # | B6: Worker / Doer | C6: Position | D6: Responsibilities
A7: 1 | B7: =Appendix!C48 -> Trần Quốc Trung | C7: Leader | D7: Test key functions and manage test plans.
A8: =ROW()-6 -> 2 | B8: Lê Chí Trường | C8: Member | D8: Test the Filter and Search functions.
A9: =ROW()-6 -> 3 | B9: =Appendix!C49 -> Nguyễn Hoàng Tú | C9: Member | D9: Design test cases and record errors for the Filter function.
A10: =ROW()-6 -> 4 | B10: =Appendix!C49 -> Nguyễn Hoàng Tú | C10: Member | D10: Test the Search and Filter functions.
A11: =ROW()-6 -> 5 | B11: Trần Duy Tân | C11: Member | D11: Test the Payment and Order Tracking functions.
A12: =ROW()-6 -> 6 | B12: =Appendix!C48 -> Trần Quốc Trung | C12: Leader | D12: Manage testing of Payment function and detailed testing.
A13: =ROW()-6 -> 7 | B13: Trần Thanh Vũ | C13: Member | D13: Test the Order Tracking and Filter functions.
A14: =ROW()-6 -> 8 | B14: Trần Duy Tân | C14: Member | D14: Design test cases for Payment and Order Tracking functions.
A15: =ROW()-6 -> 9 | B15: Lê Chí Trường | C15: Member | D15: Test Search functionality and Order Tracking support.
A16: =ROW()-6 -> 10 | B16: Nguyễn Hoàng Tú | C16: Member | D16: Test Filter and Payment functions.
A18: Master Schedule
A20: # | B20: Item | C20: Start Date | D20: End Date
A21: 1 | B21: Create test plan | C21: 45574 | D21: 45578
A22: 2 | B22: Create test design | C22: 45579 | D22: 45580
A23: 3 | B23: Create test case | C23: 45581 | D23: 45582
A24: 4 | B24: Execute test and log bugs | C24: 45585 | D24: 45588
A25: 5 | B25: Evaluting exit criteria & Test report | C25: 45588 | D25: 45590
A26: 6 | B26: Review | C26: 45591 | D26: 45595
B28: Task | C28: Start day from 9/12/2019 | D28: Duration
B29: Create test plan | C29: =INT(C21)-INT($C$21) -> 0 | D29: =(INT(D21)-INT($C$21))-(INT(C21)-INT($C$21)) -> 4
B30: Create test design | C30: =INT(C22)-INT($C$21)-1 -> 4 | D30: =(INT(D22)-INT($C$21))-(INT(C22)-INT($C$21)) -> 1
B31: Create test case | C31: =INT(C23)-INT($C$21)-2 -> 5 | D31: =(INT(D23)-INT($C$21))-(INT(C23)-INT($C$21)) -> 1
B32: Execute test and log bugs | C32: =INT(C24)-INT($C$21)-3 -> 8 | D32: =(INT(D24)-INT($C$21))-(INT(C24)-INT($C$21)) -> 3
B33: Evaluting exit criteria & Test report | C33: =INT(C25)-INT($C$21)-4 -> 10 | D33: =(INT(D25)-INT($C$21))-(INT(C25)-INT($C$21)) -> 2
B34: Review | C34: =INT(C26)-INT($C$21)-5 -> 12 | D34: =(INT(D26)-INT($C$21))-(INT(C26)-INT($C$21))+1 -> 5
A36: Detail Schedule
B37: Liên kết

Sheet Detail Schedule
A1: # | B1: Item | C1: Responsibilities | D1: October
D2: 9 | E2: 10 | F2: 11 | G2: 12 | H2: 13 | I2: 14 | J2: 15 | K2: 16 | L2: 17 | M2: 18 | N2: 19 | O2: 20 | P2: 21 | Q2: 22 | R2: 23 | S2: 24 | T2: 25 | U2: 26 | V2: 27 | W2: 28 | X2: 29 | Y2: 30 | Z2: 31
A3: 1 | B3: Create test plan | C3: Team
A4: 2 | B4: Create test design
A5: 43467 | B5: Filter - Filter by product category | C5: =Appendix!C49 -> Nguyễn Hoàng Tú
A6: 43498 | B6: Filter - Filter by price | C6: =Appendix!C49 -> Nguyễn Hoàng Tú
A7: 43526 | B7: Filter - Filter by brand | C7: =Appendix!C49 -> Nguyễn Hoàng Tú
A8: 43557 | B8: Search - Search by keyword | C8: Lê Chí Trường
A9: 43587 | B9: Payments - Online payment processing | C9: =Appendix!C48 -> Trần Quốc Trung
A10: 43618 | B10: Track orders - Update status | C10: Trần Duy Tân
A11: 43648 | B11: Profile - Update personal information | C11: Trần Thanh Vũ
A12: 43679 | B12: Review | C12: Team
A13: 3 | B13: Create test case
A14: 43468 | B14: Filter - Filter by product category | C14: =Appendix!C49 -> Nguyễn Hoàng Tú
A15: 43499 | B15: Filter - Filter by price | C15: =Appendix!C49 -> Nguyễn Hoàng Tú
A16: 43527 | B16: Filter - Filter by brand | C16: =Appendix!C49 -> Nguyễn Hoàng Tú
A17: 43558 | B17: Search - Search by keyword | C17: Lê Chí Trường
A18: 43588 | B18: Payments - Online payment processing | C18: =Appendix!C48 -> Trần Quốc Trung
A19: 43619 | B19: Track orders - Update status | C19: Trần Duy Tân
A20: 43649 | B20: Profile - Update personal information | C20: Trần Thanh Vũ
A21: 43680 | B21: Review | C21: Team
A22: 43711 | B22: Review | C22: Team
A23: 4 | B23: Execute test and logs bug
A24: 43469 | B24: Filter - Filter by product category | C24: =Appendix!C49 -> Nguyễn Hoàng Tú
A25: 43500 | B25: Filter - Filter by price | C25: =Appendix!C49 -> Nguyễn Hoàng Tú
A26: 43528 | B26: Filter - Filter by brand | C26: =Appendix!C49 -> Nguyễn Hoàng Tú
A27: 43559 | B27: Search - Search by keyword | C27: Lê Chí Trường
A28: 43589 | B28: Payments - Online payment processing | C28: =Appendix!C48 -> Trần Quốc Trung
A29: 43620 | B29: Track orders - Update status | C29: Trần Duy Tân
A30: 43650 | B30: Profile - Update personal information | C30: Trần Thanh Vũ
A31: 43681 | B31: Review | C31: Team
A32: 43712 | B32: Review | C32: Team
A33: 5 | B33: Evaluting exit criteria & Test report | C33: Team
A34: 6 | B34: Review | C34: Team | Z34: x

Sheet Appendix
D2: Appendix
B4: Term definition
B5: # | C5: Term | D5: Definition/explanation
B6: 1
B7: 2
B8: 3
B9: 4
B10: 5
B11: 6
B12: 7
B13: 8
B14: 9
B15: 10
B16: 11
B17: 12
... B21: 17
B25: Glossary
B26: #
B27: 1
B28: 1
B29: 2
B30: 3
B31: 4
B33: #
B34: 4
B35: 5
B36: 6
B37: 7
B38: 8
B39: 9
B40: 10
B41: 11
B42: 12
B43: 13
B44: 14
B47: Members
B48: 1 | C48: Trần Quốc Trung
B49: 2 | C49: Nguyễn Hoàng Tú
B50: 3 | C50: Lê Chí Trường
B51: 4 | C51: Trần Duy Tân
...
